<?xml version="1.0" ?>
<sdf version="1.6">
    <model name="sporty_quadcopter">
        <static>false</static>

        <link name="base_link">
            <pose>0 0 0.1 0 0 0</pose>
            <inertial>
                <pose>0 0 0 0 0 0</pose>
                <mass>1.8</mass>
                <inertia>
                    <ixx>0.0243</ixx>
                    <ixy>0</ixy>
                    <ixz>0</ixz>
                    <iyy>0.0243</iyy>
                    <iyz>0</iyz>
                    <izz>0.0436</izz>
                </inertia>
            </inertial>

            <visual name="body_visual">
                <geometry>
                    <box>
                        <size>0.4 0.4 0.1</size>
                    </box>
                </geometry>
                <material>
                    <ambient>0.1 0.1 0.1 1.0</ambient>
                    <diffuse>0.1 0.1 0.1 1.0</diffuse>
                </material>
            </visual>

            <collision name="body_collision">
                <geometry>
                    <box>
                        <size>0.4 0.4 0.1</size>
                    </box>
                </geometry>
            </collision>

            <sensor name="imu_sensor" type="imu">
                <always_on>1</always_on>
                <update_rate>100</update_rate>
                <pose>0 0 0 0 0 0</pose>
                <topic>imu</topic>
            </sensor>

            <sensor name="gps" type="gps">
                <always_on>1</always_on>
                <update_rate>10</update_rate>
                <pose>0 0 0 0 0 0</pose>
                <topic>gps</topic>
            </sensor>
        </link>

        <link name="rotor_front_right">
            <pose>0.15 -0.15 0.1 0 0 0</pose>
            <inertial>
                <mass>0.025</mass>
                <inertia>
                    <ixx>9.75e-06</ixx>
                    <ixy>0</ixy>
                    <ixz>0</ixz>
                    <iyy>9.75e-06</iyy>
                    <iyz>0</iyz>
                    <izz>1.8e-05</izz>
                </inertia>
            </inertial>
            <visual name="rotor1_visual">
                <geometry>
                    <cylinder>
                        <radius>0.12</radius>
                        <length>0.02</length>
                    </cylinder>
                </geometry>
                <material>
                    <ambient>1 0 0 1</ambient>
                    <diffuse>1 0 0 1</diffuse>
                </material>
            </visual>
            <collision name="rotor1_collision">
                <geometry>
                    <cylinder>
                        <radius>0.12</radius>
                        <length>0.02</length>
                    </cylinder>
                </geometry>
            </collision>
        </link>

        <link name="rotor_front_left">
            <pose>0.15 0.15 0.1 0 0 0</pose>
            <inertial>
                <mass>0.025</mass>
                <inertia>
                    <ixx>9.75e-06</ixx>
                    <ixy>0</ixy>
                    <ixz>0</ixz>
                    <iyy>9.75e-06</iyy>
                    <iyz>0</iyz>
                    <izz>1.8e-05</izz>
                </inertia>
            </inertial>
            <visual name="rotor2_visual">
                <geometry>
                    <cylinder>
                        <radius>0.12</radius>
                        <length>0.02</length>
                    </cylinder>
                </geometry>
                <material>
                    <ambient>0 0 0 1</ambient>
                    <diffuse>0 0 0 1</diffuse>
                </material>
            </visual>
            <collision name="rotor2_collision">
                <geometry>
                    <cylinder>
                        <radius>0.12</radius>
                        <length>0.02</length>
                    </cylinder>
                </geometry>
            </collision>
        </link>

        <link name="rotor_back_right">
            <pose>-0.15 -0.15 0.1 0 0 0</pose>
            <inertial>
                <mass>0.025</mass>
                <inertia>
                    <ixx>9.75e-06</ixx>
                    <ixy>0</ixy>
                    <ixz>0</ixz>
                    <iyy>9.75e-06</iyy>
                    <iyz>0</iyz>
                    <izz>1.8e-05</izz>
                </inertia>
            </inertial>
            <visual name="rotor3_visual">
                <geometry>
                    <cylinder>
                        <radius>0.12</radius>
                        <length>0.02</length>
                    </cylinder>
                </geometry>
                <material>
                    <ambient>0 0 0 1</ambient>
                    <diffuse>0 0 0 1</diffuse>
                </material>
            </visual>
            <collision name="rotor3_collision">
                <geometry>
                    <cylinder>
                        <radius>0.12</radius>
                        <length>0.02</length>
                    </cylinder>
                </geometry>
            </collision>
        </link>

        <link name="rotor_back_left">
            <pose>-0.15 0.15 0.1 0 0 0</pose>
            <inertial>
                <mass>0.025</mass>
                <inertia>
                    <ixx>9.75e-06</ixx>
                    <ixy>0</ixy>
                    <ixz>0</ixz>
                    <iyy>9.75e-06</iyy>
                    <iyz>0</iyz>
                    <izz>1.8e-05</izz>
                </inertia>
            </inertial>
            <visual name="rotor4_visual">
                <geometry>
                    <cylinder>
                        <radius>0.12</radius>
                        <length>0.02</length>
                    </cylinder>
                </geometry>
                <material>
                    <ambient>1 0 0 1</ambient>
                    <diffuse>1 0 0 1</diffuse>
                </material>
            </visual>
            <collision name="rotor4_collision">
                <geometry>
                    <cylinder>
                        <radius>0.12</radius>
                        <length>0.02</length>
                    </cylinder>
                </geometry>
            </collision>
        </link>

        <joint name="rotor_front_right_joint" type="revolute">
            <parent>base_link</parent>
            <child>rotor_front_right</child>
            <axis>
                <xyz>0 0 1</xyz>
            </axis>
        </joint>

        <joint name="rotor_front_left_joint" type="revolute">
            <parent>base_link</parent>
            <child>rotor_front_left</child>
            <axis>
                <xyz>0 0 1</xyz>
            </axis>
        </joint>

        <joint name="rotor_back_right_joint" type="revolute">
            <parent>base_link</parent>
            <child>rotor_back_right</child>
            <axis>
                <xyz>0 0 1</xyz>
            </axis>
        </joint>

        <joint name="rotor_back_left_joint" type="revolute">
            <parent>base_link</parent>
            <child>rotor_back_left</child>
            <axis>
                <xyz>0 0 1</xyz>
            </axis>
        </joint>

        <plugin name="multirotor_base_plugin" filename="libgazebo_multirotor_base_plugin.so">
            <robotNamespace></robotNamespace>
            <motorSpeed>1100</motorSpeed>
            <torqueConstant>8.54858e-06</torqueConstant>
            <timeConstant>0.01</timeConstant>
            <maxRotVelocity>838</maxRotVelocity>
            <rotorVelocitySlowdownSim>10</rotorVelocitySlowdownSim>
        </plugin>
    </model>
</sdf>